Workbook

Sheet global_params
A1: descripcion | B1: valor | C1: observaciones
A2: Escenario Base | B2: 0
A3: Tasa general ITBIS base | B3: 18 | C3: Porcentaje
A4: Ajustar transferencias? | B4: 1 | C4: 0 = No, 1= Sí
A5: Simular transferencias compensatorias? | B5: 1 | C5: 0 = No, 1= Sí
A6: Enviar resultados a Excel | B6: 1 | C6: 0 = No, 1= Sí
A7: Grupo a ser compensado | B7: 2 | C7: 1: Fpobre 1 y 2 2:Fpobre 1 al 3
A8: Tipo de establecimiento | B8: 4 | C8: 1: 66% formales, 2: 83% formales 3:100% formales 4;86% formales (!nuevo)
A9: Valor de compensación | B9: 1145 | C9: Pesos dominicanos al mes
A10: Valor de comer es primero | B10: 1650 | C10: Pesos dominicanos
A11: Resumen | B11: 1
A12: Sensibilidad | B12: 1
A13: valor fijo superate | B13: 1 | C13: agregado oct 2024
A14: valor nuevo superate | B14: 350 | C14: agregado oct 2024
A15: total subsidios | B15: =1554.6*59.4086 -> 92356.61 | C15: millones 2024
A16: total ITBIS | B16: 375087.6 | C16: millones 2024
A17: total impuesto sobre la renta | B17: 91423.69 | C17: millones 2024
A18: PIB | B18: 5866760.5 | C18: millones 2024
A19: total mensual subsidio | B19: =B18*0.005 -> 29333.802 | C19: millones 2024

Sheet escenarios
A1: escenario | B1: activo | C1: comparativo | D1: sim_itbis | E1: sim_renta | F1: sim_sub | G1: sim_sgas | H1: sim_com | I1: des_escenario | J1: des_corto
A2: 1 | B2: 1 | C2: 1 | D2: 1 | E2: 1 | F2: 1 | G2: 1 | H2: 1 | I2: =_xlfn.LET( _xlpm.itbis, IF(D2<>0, VLOOKUP(D2, sim_itbis!$A$1:$F$8, 6, 0), ""), _xlpm.renta, IF(E2<>0, VLOOKUP(E2, sim_renta!$A$2:$W$11, 23, 0), ""), _xlpm.sub, IF(F2<>0, VLOOKUP(F2, sim_sub!$A$2:$BF$11, 58, 0), ""), _xlpm.sgas, IF(G2<>0, VLOOKUP(G2, sim_sgas!$A$1:$GA$11, 183, 0), ""), _xlpm.lista, _xlfn.TEXTJOIN(", ", TRUE, _xlpm.itbis, _xlpm.renta, _xlpm.sub, _xlpm.sgas), _xlpm.num_comas, LEN(_xlpm.lista) - LEN(SUBSTITUTE(_xlpm.lista, ",", "")), _xlpm.texto_final, IF(_xlpm.num_comas=0, _xlpm.lista, SUBSTITUTE(_xlpm.lista, ", ", " y ", _xlpm.num_comas)), _xlpm.texto_final & IF(H2<>0, " (compensación)", "") ) -> Exentos al 10%, ISR reforma, Ajuste subsidio eléctrico y subsidio combustibles (compensación) | J2: Exentos al 10%
A3: 2 | B3: 0 | C3: 1 | D3: 1 | E3: 0 | F3: 0 | G3: 0 | H3: 1 | I3: =_xlfn.LET( _xlpm.itbis, IF(D3<>0, VLOOKUP(D3, sim_itbis!$A$1:$F$8, 6, 0), ""), _xlpm.renta, IF(E3<>0, VLOOKUP(E3, sim_renta!$A$2:$W$11, 23, 0), ""), _xlpm.sub, IF(F3<>0, VLOOKUP(F3, sim_sub!$A$2:$BF$11, 58, 0), ""), _xlpm.sgas, IF(G3<>0, VLOOKUP(G3, sim_sgas!$A$1:$GA$11, 183, 0), ""), _xlpm.lista, _xlfn.TEXTJOIN(", ", TRUE, _xlpm.itbis, _xlpm.renta, _xlpm.sub, _xlpm.sgas), _xlpm.num_comas, LEN(_xlpm.lista) - LEN(SUBSTITUTE(_xlpm.lista, ",", "")), _xlpm.texto_final, IF(_xlpm.num_comas=0, _xlpm.lista, SUBSTITUTE(_xlpm.lista, ", ", " y ", _xlpm.num_comas)), _xlpm.texto_final & IF(H3<>0, " (compensación)", "") ) -> Exentos al 10% (compensación) | J3: Exentos al 10% compensación
A4: 3 | B4: 0 | C4: 2 | D4: 2 | E4: 0 | F4: 0 | G4: 0 | H4: 0 | I4: =_xlfn.LET( _xlpm.itbis, IF(D4<>0, VLOOKUP(D4, sim_itbis!$A$1:$F$8, 6, 0), ""), _xlpm.renta, IF(E4<>0, VLOOKUP(E4, sim_renta!$A$2:$W$11, 23, 0), ""), _xlpm.sub, IF(F4<>0, VLOOKUP(F4, sim_sub!$A$2:$BF$11, 58, 0), ""), _xlpm.sgas, IF(G4<>0, VLOOKUP(G4, sim_sgas!$A$1:$GA$11, 183, 0), ""), _xlpm.lista, _xlfn.TEXTJOIN(", ", TRUE, _xlpm.itbis, _xlpm.renta, _xlpm.sub, _xlpm.sgas), _xlpm.num_comas, LEN(_xlpm.lista) - LEN(SUBSTITUTE(_xlpm.lista, ",", "")), _xlpm.texto_final, IF(_xlpm.num_comas=0, _xlpm.lista, SUBSTITUTE(_xlpm.lista, ", ", " y ", _xlpm.num_comas)), _xlpm.texto_final & IF(H4<>0, " (compensación)", "") ) -> ITBIS tasa 16% | J4: Tasa 16%
A5: 4 | B5: 0 | C5: 2 | D5: 2 | E5: 0 | F5: 0 | G5: 0 | H5: 1 | I5: =_xlfn.LET( _xlpm.itbis, IF(D5<>0, VLOOKUP(D5, sim_itbis!$A$1:$F$8, 6, 0), ""), _xlpm.renta, IF(E5<>0, VLOOKUP(E5, sim_renta!$A$2:$W$11, 23, 0), ""), _xlpm.sub, IF(F5<>0, VLOOKUP(F5, sim_sub!$A$2:$BF$11, 58, 0), ""), _xlpm.sgas, IF(G5<>0, VLOOKUP(G5, sim_sgas!$A$1:$GA$11, 183, 0), ""), _xlpm.lista, _xlfn.TEXTJOIN(", ", TRUE, _xlpm.itbis, _xlpm.renta, _xlpm.sub, _xlpm.sgas), _xlpm.num_comas, LEN(_xlpm.lista) - LEN(SUBSTITUTE(_xlpm.lista, ",", "")), _xlpm.texto_final, IF(_xlpm.num_comas=0, _xlpm.lista, SUBSTITUTE(_xlpm.lista, ", ", " y ", _xlpm.num_comas)), _xlpm.texto_final & IF(H5<>0, " (compensación)", "") ) -> ITBIS tasa 16% (compensación) | J5: Tasa 16% compensación
A6: 5 | B6: 0 | C6: 3 | D6: 0 | E6: 0 | F6: 1 | G6: 0 | H6: 0 | I6: =_xlfn.LET( _xlpm.itbis, IF(D6<>0, VLOOKUP(D6, sim_itbis!$A$1:$F$8, 6, 0), ""), _xlpm.renta, IF(E6<>0, VLOOKUP(E6, sim_renta!$A$2:$W$11, 23, 0), ""), _xlpm.sub, IF(F6<>0, VLOOKUP(F6, sim_sub!$A$2:$BF$11, 58, 0), ""), _xlpm.sgas, IF(G6<>0, VLOOKUP(G6, sim_sgas!$A$1:$GA$11, 183, 0), ""), _xlpm.lista, _xlfn.TEXTJOIN(", ", TRUE, _xlpm.itbis, _xlpm.renta, _xlpm.sub, _xlpm.sgas), _xlpm.num_comas, LEN(_xlpm.lista) - LEN(SUBSTITUTE(_xlpm.lista, ",", "")), _xlpm.texto_final, IF(_xlpm.num_comas=0, _xlpm.lista, SUBSTITUTE(_xlpm.lista, ", ", " y ", _xlpm.num_comas)), _xlpm.texto_final & IF(H6<>0, " (compensación)", "") ) -> Ajuste subsidio eléctrico | J6: Ajuste subsidio
A7: 6 | B7: 0 | C7: 21 | D7: 0 | E7: 0 | F7: 2 | G7: 0 | H7: 0 | I7: =_xlfn.LET( _xlpm.itbis, IF(D7<>0, VLOOKUP(D7, sim_itbis!$A$1:$F$8, 6, 0), ""), _xlpm.renta, IF(E7<>0, VLOOKUP(E7, sim_renta!$A$2:$W$11, 23, 0), ""), _xlpm.sub, IF(F7<>0, VLOOKUP(F7, sim_sub!$A$2:$BF$11, 58, 0), ""), _xlpm.sgas, IF(G7<>0, VLOOKUP(G7, sim_sgas!$A$1:$GA$11, 183, 0), ""), _xlpm.lista, _xlfn.TEXTJOIN(", ", TRUE, _xlpm.itbis, _xlpm.renta, _xlpm.sub, _xlpm.sgas), _xlpm.num_comas, LEN(_xlpm.lista) - LEN(SUBSTITUTE(_xlpm.lista, ",", "")), _xlpm.texto_final, IF(_xlpm.num_comas=0, _xlpm.lista, SUBSTITUTE(_xlpm.lista, ", ", " y ", _xlpm.num_comas)), _xlpm.texto_final & IF(H7<>0, " (compensación)", "") ) -> Sin subsidio | J7: Sin subsidio
A8: 7 | B8: 0 | C8: 21 | D8: 0 | E8: 0 | F8: 1 | G8: 1 | H8: 0 | I8: =_xlfn.LET( _xlpm.itbis, IF(D8<>0, VLOOKUP(D8, sim_itbis!$A$1:$F$8, 6, 0), ""), _xlpm.renta, IF(E8<>0, VLOOKUP(E8, sim_renta!$A$2:$W$11, 23, 0), ""), _xlpm.sub, IF(F8<>0, VLOOKUP(F8, sim_sub!$A$2:$BF$11, 58, 0), ""), _xlpm.sgas, IF(G8<>0, VLOOKUP(G8, sim_sgas!$A$1:$GA$11, 183, 0), ""), _xlpm.lista, _xlfn.TEXTJOIN(", ", TRUE, _xlpm.itbis, _xlpm.renta, _xlpm.sub, _xlpm.sgas), _xlpm.num_comas, LEN(_xlpm.lista) - LEN(SUBSTITUTE(_xlpm.lista, ",", "")), _xlpm.texto_final, IF(_xlpm.num_comas=0, _xlpm.lista, SUBSTITUTE(_xlpm.lista, ", ", " y ", _xlpm.num_comas)), _xlpm.texto_final & IF(H8<>0, " (compensación)", "") ) -> Ajuste subsidio eléctrico y subsidio combustibles | J8: Subsidio combustibles
A9: 8 | B9: 0 | C9: 2 | D9: 2 | E9: 1 | F9: 1 | G9: 1 | H9: 1 | I9: =_xlfn.LET( _xlpm.itbis, IF(D9<>0, VLOOKUP(D9, sim_itbis!$A$1:$F$8, 6, 0), ""), _xlpm.renta, IF(E9<>0, VLOOKUP(E9, sim_renta!$A$2:$W$11, 23, 0), ""), _xlpm.sub, IF(F9<>0, VLOOKUP(F9, sim_sub!$A$2:$BF$11, 58, 0), ""), _xlpm.sgas, IF(G9<>0, VLOOKUP(G9, sim_sgas!$A$1:$GA$11, 183, 0), ""), _xlpm.lista, _xlfn.TEXTJOIN(", ", TRUE, _xlpm.itbis, _xlpm.renta, _xlpm.sub, _xlpm.sgas), _xlpm.num_comas, LEN(_xlpm.lista) - LEN(SUBSTITUTE(_xlpm.lista, ",", "")), _xlpm.texto_final, IF(_xlpm.num_comas=0, _xlpm.lista, SUBSTITUTE(_xlpm.lista, ", ", " y ", _xlpm.num_comas)), _xlpm.texto_final & IF(H9<>0, " (compensación)", "") ) -> ITBIS tasa 16% , ISR reforma, Ajuste subsidio eléctrico y subsidio combustibles (compensación)
A10: 9 | B10: 0 | C10: 11 | D10: 0 | E10: 1 | F10: 0 | H10: 0 | I10: =_xlfn.LET( _xlpm.itbis, IF(D10<>0, VLOOKUP(D10, sim_itbis!$A$1:$F$8, 6, 0), ""), _xlpm.renta, IF(E10<>0, VLOOKUP(E10, sim_renta!$A$2:$W$11, 23, 0), ""), _xlpm.sub, IF(F10<>0, VLOOKUP(F10, sim_sub!$A$2:$BF$11, 58, 0), ""), _xlpm.sgas, IF(G10<>0, VLOOKUP(G10, sim_sgas!$A$1:$GA$11, 183, 0), ""), _xlpm.lista, _xlfn.TEXTJOIN(", ", TRUE, _xlpm.itbis, _xlpm.renta, _xlpm.sub, _xlpm.sgas), _xlpm.num_comas, LEN(_xlpm.lista) - LEN(SUBSTITUTE(_xlpm.lista, ",", "")), _xlpm.texto_final, IF(_xlpm.num_comas=0, _xlpm.lista, SUBSTITUTE(_xlpm.lista, ", ", " y ", _xlpm.num_comas)), _xlpm.texto_final & IF(H10<>0, " (compensación)", "") ) -> ISR reforma
A11: 10 | B11: 0 | C11: 11 | D11: 0 | E11: 1 | F11: 0 | H11: 1 | I11: =_xlfn.LET( _xlpm.itbis, IF(D11<>0, VLOOKUP(D11, sim_itbis!$A$1:$F$8, 6, 0), ""), _xlpm.renta, IF(E11<>0, VLOOKUP(E11, sim_renta!$A$2:$W$11, 23, 0), ""), _xlpm.sub, IF(F11<>0, VLOOKUP(F11, sim_sub!$A$2:$BF$11, 58, 0), ""), _xlpm.sgas, IF(G11<>0, VLOOKUP(G11, sim_sgas!$A$1:$GA$11, 183, 0), ""), _xlpm.lista, _xlfn.TEXTJOIN(", ", TRUE, _xlpm.itbis, _xlpm.renta, _xlpm.sub, _xlpm.sgas), _xlpm.num_comas, LEN(_xlpm.lista) - LEN(SUBSTITUTE(_xlpm.lista, ",", "")), _xlpm.texto_final, IF(_xlpm.num_comas=0, _xlpm.lista, SUBSTITUTE(_xlpm.lista, ", ", " y ", _xlpm.num_comas)), _xlpm.texto_final & IF(H11<>0, " (compensación)", "") ) -> ISR reforma (compensación)
A12: 11 | B12: 0 | C12: 21 | D12: 0 | E12: 0 | F12: 1 | H12: 0 | I12: =_xlfn.LET( _xlpm.itbis, IF(D12<>0, VLOOKUP(D12, sim_itbis!$A$1:$F$8, 6, 0), ""), _xlpm.renta, IF(E12<>0, VLOOKUP(E12, sim_renta!$A$2:$W$11, 23, 0), ""), _xlpm.sub, IF(F12<>0, VLOOKUP(F12, sim_sub!$A$2:$BF$11, 58, 0), ""), _xlpm.sgas, IF(G12<>0, VLOOKUP(G12, sim_sgas!$A$1:$GA$11, 183, 0), ""), _xlpm.lista, _xlfn.TEXTJOIN(", ", TRUE, _xlpm.itbis, _xlpm.renta, _xlpm.sub, _xlpm.sgas), _xlpm.num_comas, LEN(_xlpm.lista) - LEN(SUBSTITUTE(_xlpm.lista, ",", "")), _xlpm.texto_final, IF(_xlpm.num_comas=0, _xlpm.lista, SUBSTITUTE(_xlpm.lista, ", ", " y ", _xlpm.num_comas)), _xlpm.texto_final & IF(H12<>0, " (compensación)", "") ) -> Ajuste subsidio eléctrico
A13: 12 | B13: 0 | D13: 0 | E13: 0 | F13: 1 | H13: 0 | I13: =_xlfn.LET( _xlpm.itbis, IF(D13<>0, VLOOKUP(D13, sim_itbis!$A$1:$F$8, 6, 0), ""), _xlpm.renta, IF(E13<>0, VLOOKUP(E13, sim_renta!$A$2:$W$11, 23, 0), ""), _xlpm.sub, IF(F13<>0, VLOOKUP(F13, sim_sub!$A$2:$BF$11, 58, 0), ""), _xlpm.sgas, IF(G13<>0, VLOOKUP(G13, sim_sgas!$A$1:$GA$11, 183, 0), ""), _xlpm.lista, _xlfn.TEXTJOIN(", ", TRUE, _xlpm.itbis, _xlpm.renta, _xlpm.sub, _xlpm.sgas), _xlpm.num_comas, LEN(_xlpm.lista) - LEN(SUBSTITUTE(_xlpm.lista, ",", "")), _xlpm.texto_final, IF(_xlpm.num_comas=0, _xlpm.lista, SUBSTITUTE(_xlpm.lista, ", ", " y ", _xlpm.num_comas)), _xlpm.texto_final & IF(H13<>0, " (compensación)", "") ) -> Ajuste subsidio eléctrico
A14: 13 | B14: 0 | D14: 4 | E14: 1 | H14: 1 | I14: =_xlfn.LET( _xlpm.itbis, IF(D14<>0, VLOOKUP(D14, sim_itbis!$A$1:$F$8, 6, 0), ""), _xlpm.renta, IF(E14<>0, VLOOKUP(E14, sim_renta!$A$2:$W$11, 23, 0), ""), _xlpm.sub, IF(F14<>0, VLOOKUP(F14, sim_sub!$A$2:$BF$11, 58, 0), ""), _xlpm.sgas, IF(G14<>0, VLOOKUP(G14, sim_sgas!$A$1:$GA$11, 183, 0), ""), _xlpm.lista, _xlfn.TEXTJOIN(", ", TRUE, _xlpm.itbis, _xlpm.renta, _xlpm.sub, _xlpm.sgas), _xlpm.num_comas, LEN(_xlpm.lista) - LEN(SUBSTITUTE(_xlpm.lista, ",", "")), _xlpm.texto_final, IF(_xlpm.num_comas=0, _xlpm.lista, SUBSTITUTE(_xlpm.lista, ", ", " y ", _xlpm.num_comas)), _xlpm.texto_final & IF(H14<>0, " (compensación)", "") ) -> ITBIS 16 (menos 11 productos) y ISR reforma (compensación)
A15: 14 | B15: 0 | D15: 0 | E15: 1 | H15: 1 | I15: =_xlfn.LET( _xlpm.itbis, IF(D15<>0, VLOOKUP(D15, sim_itbis!$A$1:$F$8, 6, 0), ""), _xlpm.renta, IF(E15<>0, VLOOKUP(E15, sim_renta!$A$2:$W$11, 23, 0), ""), _xlpm.sub, IF(F15<>0, VLOOKUP(F15, sim_sub!$A$2:$BF$11, 58, 0), ""), _xlpm.sgas, IF(G15<>0, VLOOKUP(G15, sim_sgas!$A$1:$GA$11, 183, 0), ""), _xlpm.lista, _xlfn.TEXTJOIN(", ", TRUE, _xlpm.itbis, _xlpm.renta, _xlpm.sub, _xlpm.sgas), _xlpm.num_comas, LEN(_xlpm.lista) - LEN(SUBSTITUTE(_xlpm.lista, ",", "")), _xlpm.texto_final, IF(_xlpm.num_comas=0, _xlpm.lista, SUBSTITUTE(_xlpm.lista, ", ", " y ", _xlpm.num_comas)), _xlpm.texto_final & IF(H15<>0, " (compensación)", "") ) -> ISR reforma (compensación)
A16: 15 | B16: 0 | D16: 1 | E16: 0 | H16: 1 | I16: =_xlfn.LET( _xlpm.itbis, IF(D16<>0, VLOOKUP(D16, sim_itbis!$A$1:$F$8, 6, 0), ""), _xlpm.renta, IF(E16<>0, VLOOKUP(E16, sim_renta!$A$2:$W$11, 23, 0), ""), _xlpm.sub, IF(F16<>0, VLOOKUP(F16, sim_sub!$A$2:$BF$11, 58, 0), ""), _xlpm.sgas, IF(G16<>0, VLOOKUP(G16, sim_sgas!$A$1:$GA$11, 183, 0), ""), _xlpm.lista, _xlfn.TEXTJOIN(", ", TRUE, _xlpm.itbis, _xlpm.renta, _xlpm.sub, _xlpm.sgas), _xlpm.num_comas, LEN(_xlpm.lista) - LEN(SUBSTITUTE(_xlpm.lista, ",", "")), _xlpm.texto_final, IF(_xlpm.num_comas=0, _xlpm.lista, SUBSTITUTE(_xlpm.lista, ", ", " y ", _xlpm.num_comas)), _xlpm.texto_final & IF(H16<>0, " (compensación)", "") ) -> Exentos al 10% (compensación)
A17: 16 | B17: 0 | D17: 2 | E17: 0 | H17: 1 | I17: =_xlfn.LET( _xlpm.itbis, IF(D17<>0, VLOOKUP(D17, sim_itbis!$A$1:$F$8, 6, 0), ""), _xlpm.renta, IF(E17<>0, VLOOKUP(E17, sim_renta!$A$2:$W$11, 23, 0), ""), _xlpm.sub, IF(F17<>0, VLOOKUP(F17, sim_sub!$A$2:$BF$11, 58, 0), ""), _xlpm.sgas, IF(G17<>0, VLOOKUP(G17, sim_sgas!$A$1:$GA$11, 183, 0), ""), _xlpm.lista, _xlfn.TEXTJOIN(", ", TRUE, _xlpm.itbis, _xlpm.renta, _xlpm.sub, _xlpm.sgas), _xlpm.num_comas, LEN(_xlpm.lista) - LEN(SUBSTITUTE(_xlpm.lista, ",", "")), _xlpm.texto_final, IF(_xlpm.num_comas=0, _xlpm.lista, SUBSTITUTE(_xlpm.lista, ", ", " y ", _xlpm.num_comas)), _xlpm.texto_final & IF(H17<>0, " (compensación)", "") ) -> ITBIS tasa 16% (compensación)
A18: 17 | B18: 0 | D18: 3 | E18: 0 | H18: 1 | I18: =_xlfn.LET( _xlpm.itbis, IF(D18<>0, VLOOKUP(D18, sim_itbis!$A$1:$F$8, 6, 0), ""), _xlpm.renta, IF(E18<>0, VLOOKUP(E18, sim_renta!$A$2:$W$11, 23, 0), ""), _xlpm.sub, IF(F18<>0, VLOOKUP(F18, sim_sub!$A$2:$BF$11, 58, 0), ""), _xlpm.sgas, IF(G18<>0, VLOOKUP(G18, sim_sgas!$A$1:$GA$11, 183, 0), ""), _xlpm.lista, _xlfn.TEXTJOIN(", ", TRUE, _xlpm.itbis, _xlpm.renta, _xlpm.sub, _xlpm.sgas), _xlpm.num_comas, LEN(_xlpm.lista) - LEN(SUBSTITUTE(_xlpm.lista, ",", "")), _xlpm.texto_final, IF(_xlpm.num_comas=0, _xlpm.lista, SUBSTITUTE(_xlpm.lista, ", ", " y ", _xlpm.num_comas)), _xlpm.texto_final & IF(H18<>0, " (compensación)", "") ) -> ITBIS tasa única 16 (compensación)
A19: 18 | B19: 0 | D19: 4 | E19: 0 | H19: 1 | I19: =_xlfn.LET( _xlpm.itbis, IF(D19<>0, VLOOKUP(D19, sim_itbis!$A$1:$F$8, 6, 0), ""), _xlpm.renta, IF(E19<>0, VLOOKUP(E19, sim_renta!$A$2:$W$11, 23, 0), ""), _xlpm.sub, IF(F19<>0, VLOOKUP(F19, sim_sub!$A$2:$BF$11, 58, 0), ""), _xlpm.sgas, IF(G19<>0, VLOOKUP(G19, sim_sgas!$A$1:$GA$11, 183, 0), ""), _xlpm.lista, _xlfn.TEXTJOIN(", ", TRUE, _xlpm.itbis, _xlpm.renta, _xlpm.sub, _xlpm.sgas), _xlpm.num_comas, LEN(_xlpm.lista) - LEN(SUBSTITUTE(_xlpm.lista, ",", "")), _xlpm.texto_final, IF(_xlpm.num_comas=0, _xlpm.lista, SUBSTITUTE(_xlpm.lista, ", ", " y ", _xlpm.num_comas)), _xlpm.texto_final & IF(H19<>0, " (compensación)", "") ) -> ITBIS 16 (menos 11 productos) (compensación)
A20: 19 | B20: 0 | D20: 3 | E20: 2 | H20: 0 | I20: =_xlfn.LET( _xlpm.itbis, IF(D20<>0, VLOOKUP(D20, sim_itbis!$A$1:$F$8, 6, 0), ""), _xlpm.renta, IF(E20<>0, VLOOKUP(E20, sim_renta!$A$2:$W$11, 23, 0), ""), _xlpm.sub, IF(F20<>0, VLOOKUP(F20, sim_sub!$A$2:$BF$11, 58, 0), ""), _xlpm.sgas, IF(G20<>0, VLOOKUP(G20, sim_sgas!$A$1:$GA$11, 183, 0), ""), _xlpm.lista, _xlfn.TEXTJOIN(", ", TRUE, _xlpm.itbis, _xlpm.renta, _xlpm.sub, _xlpm.sgas), _xlpm.num_comas, LEN(_xlpm.lista) - LEN(SUBSTITUTE(_xlpm.lista, ",", "")), _xlpm.texto_final, IF(_xlpm.num_comas=0, _xlpm.lista, SUBSTITUTE(_xlpm.lista, ", ", " y ", _xlpm.num_comas)), _xlpm.texto_final & IF(H20<>0, " (compensación)", "") ) -> ITBIS tasa única 16
A21: 20 | B21: 0 | D21: 4 | E21: 2 | H21: 0 | I21: =_xlfn.LET( _xlpm.itbis, IF(D21<>0, VLOOKUP(D21, sim_itbis!$A$1:$F$8, 6, 0), ""), _xlpm.renta, IF(E21<>0, VLOOKUP(E21, sim_renta!$A$2:$W$11, 23, 0), ""), _xlpm.sub, IF(F21<>0, VLOOKUP(F21, sim_sub!$A$2:$BF$11, 58, 0), ""), _xlpm.sgas, IF(G21<>0, VLOOKUP(G21, sim_sgas!$A$1:$GA$11, 183, 0), ""), _xlpm.lista, _xlfn.TEXTJOIN(", ", TRUE, _xlpm.itbis, _xlpm.renta, _xlpm.sub, _xlpm.sgas), _xlpm.num_comas, LEN(_xlpm.lista) - LEN(SUBSTITUTE(_xlpm.lista, ",", "")), _xlpm.texto_final, IF(_xlpm.num_comas=0, _xlpm.lista, SUBSTITUTE(_xlpm.lista, ", ", " y ", _xlpm.num_comas)), _xlpm.texto_final & IF(H21<>0, " (compensación)", "") ) -> ITBIS 16 (menos 11 productos)
A22: 21 | B22: 0 | D22: 5 | E22: 2 | H22: 0 | I22: =_xlfn.LET( _xlpm.itbis, IF(D22<>0, VLOOKUP(D22, sim_itbis!$A$1:$F$8, 6, 0), ""), _xlpm.renta, IF(E22<>0, VLOOKUP(E22, sim_renta!$A$2:$W$11, 23, 0), ""), _xlpm.sub, IF(F22<>0, VLOOKUP(F22, sim_sub!$A$2:$BF$11, 58, 0), ""), _xlpm.sgas, IF(G22<>0, VLOOKUP(G22, sim_sgas!$A$1:$GA$11, 183, 0), ""), _xlpm.lista, _xlfn.TEXTJOIN(", ", TRUE, _xlpm.itbis, _xlpm.renta, _xlpm.sub, _xlpm.sgas), _xlpm.num_comas, LEN(_xlpm.lista) - LEN(SUBSTITUTE(_xlpm.lista, ",", "")), _xlpm.texto_final, IF(_xlpm.num_comas=0, _xlpm.lista, SUBSTITUTE(_xlpm.lista, ", ", " y ", _xlpm.num_comas)), _xlpm.texto_final & IF(H22<>0, " (compensación)", "") )
A23: 22 | B23: 0 | D23: 6 | E23: 2 | H23: 0 | I23: =_xlfn.LET( _xlpm.itbis, IF(D23<>0, VLOOKUP(D23, sim_itbis!$A$1:$F$8, 6, 0), ""), _xlpm.renta, IF(E23<>0, VLOOKUP(E23, sim_renta!$A$2:$W$11, 23, 0), ""), _xlpm.sub, IF(F23<>0, VLOOKUP(F23, sim_sub!$A$2:$BF$11, 58, 0), ""), _xlpm.sgas, IF(G23<>0, VLOOKUP(G23, sim_sgas!$A$1:$GA$11, 183, 0), ""), _xlpm.lista, _xlfn.TEXTJOIN(", ", TRUE, _xlpm.itbis, _xlpm.renta, _xlpm.sub, _xlpm.sgas), _xlpm.num_comas, LEN(_xlpm.lista) - LEN(SUBSTITUTE(_xlpm.lista, ",", "")), _xlpm.texto_final, IF(_xlpm.num_comas=0, _xlpm.lista, SUBSTITUTE(_xlpm.lista, ", ", " y ", _xlpm.num_comas)), _xlpm.texto_final & IF(H23<>0, " (compensación)", "") )
A24: 23 | B24: 0 | D24: 6 | E24: 2 | H24: 0 | I24: =_xlfn.LET( _xlpm.itbis, IF(D24<>0, VLOOKUP(D24, sim_itbis!$A$1:$F$8, 6, 0), ""), _xlpm.renta, IF(E24<>0, VLOOKUP(E24, sim_renta!$A$2:$W$11, 23, 0), ""), _xlpm.sub, IF(F24<>0, VLOOKUP(F24, sim_sub!$A$2:$BF$11, 58, 0), ""), _xlpm.sgas, IF(G24<>0, VLOOKUP(G24, sim_sgas!$A$1:$GA$11, 183, 0), ""), _xlpm.lista, _xlfn.TEXTJOIN(", ", TRUE, _xlpm.itbis, _xlpm.renta, _xlpm.sub, _xlpm.sgas), _xlpm.num_comas, LEN(_xlpm.lista) - LEN(SUBSTITUTE(_xlpm.lista, ",", "")), _xlpm.texto_final, IF(_xlpm.num_comas=0, _xlpm.lista, SUBSTITUTE(_xlpm.lista, ", ", " y ", _xlpm.num_comas)), _xlpm.texto_final & IF(H24<>0, " (compensación)", "") )
A25: 24 | B25: 0 | D25: 6 | E25: 2 | H25: 0 | I25: =_xlfn.LET( _xlpm.itbis, IF(D25<>0, VLOOKUP(D25, sim_itbis!$A$1:$F$8, 6, 0), ""), _xlpm.renta, IF(E25<>0, VLOOKUP(E25, sim_renta!$A$2:$W$11, 23, 0), ""), _xlpm.sub, IF(F25<>0, VLOOKUP(F25, sim_sub!$A$2:$BF$11, 58, 0), ""), _xlpm.sgas, IF(G25<>0, VLOOKUP(G25, sim_sgas!$A$1:$GA$11, 183, 0), ""), _xlpm.lista, _xlfn.TEXTJOIN(", ", TRUE, _xlpm.itbis, _xlpm.renta, _xlpm.sub, _xlpm.sgas), _xlpm.num_comas, LEN(_xlpm.lista) - LEN(SUBSTITUTE(_xlpm.lista, ",", "")), _xlpm.texto_final, IF(_xlpm.num_comas=0, _xlpm.lista, SUBSTITUTE(_xlpm.lista, ", ", " y ", _xlpm.num_comas)), _xlpm.texto_final & IF(H25<>0, " (compensación)", "") )
... A27: 26 | B27: 0 | D27: 6 | E27: 2 | H27: 0 | I27: =_xlfn.LET( _xlpm.itbis, IF(D27<>0, VLOOKUP(D27, sim_itbis!$A$1:$F$8, 6, 0), ""), _xlpm.renta, IF(E27<>0, VLOOKUP(E27, sim_renta!$A$2:$W$11, 23, 0), ""), _xlpm.sub, IF(F27<>0, VLOOKUP(F27, sim_sub!$A$2:$BF$11, 58, 0), ""), _xlpm.sgas, IF(G27<>0, VLOOKUP(G27, sim_sgas!$A$1:$GA$11, 183, 0), ""), _xlpm.lista, _xlfn.TEXTJOIN(", ", TRUE, _xlpm.itbis, _xlpm.renta, _xlpm.sub, _xlpm.sgas), _xlpm.num_comas, LEN(_xlpm.lista) - LEN(SUBSTITUTE(_xlpm.lista, ",", "")), _xlpm.texto_final, IF(_xlpm.num_comas=0, _xlpm.lista, SUBSTITUTE(_xlpm.lista, ", ", " y ", _xlpm.num_comas)), _xlpm.texto_final & IF(H27<>0, " (compensación)", "") )
A28: 27 | B28: 0 | C28: 1 | D28: 1 | E28: 0 | F28: 0 | H28: 0 | I28: =_xlfn.LET( _xlpm.itbis, IF(D28<>0, VLOOKUP(D28, sim_itbis!$A$1:$F$8, 6, 0), ""), _xlpm.renta, IF(E28<>0, VLOOKUP(E28, sim_renta!$A$2:$W$11, 23, 0), ""), _xlpm.sub, IF(F28<>0, VLOOKUP(F28, sim_sub!$A$2:$BF$11, 58, 0), ""), _xlpm.sgas, IF(G28<>0, VLOOKUP(G28, sim_sgas!$A$1:$GA$11, 183, 0), ""), _xlpm.lista, _xlfn.TEXTJOIN(", ", TRUE, _xlpm.itbis, _xlpm.renta, _xlpm.sub, _xlpm.sgas), _xlpm.num_comas, LEN(_xlpm.lista) - LEN(SUBSTITUTE(_xlpm.lista, ",", "")), _xlpm.texto_final, IF(_xlpm.num_comas=0, _xlpm.lista, SUBSTITUTE(_xlpm.lista, ", ", " y ", _xlpm.num_comas)), _xlpm.texto_final & IF(H28<>0, " (compensación)", "") ) -> Exentos al 10%
A29: 28 | B29: 0 | C29: 1 | D29: 1 | E29: 1 | F29: 0 | H29: 0 | I29: =_xlfn.LET( _xlpm.itbis, IF(D29<>0, VLOOKUP(D29, sim_itbis!$A$1:$F$8, 6, 0), ""), _xlpm.renta, IF(E29<>0, VLOOKUP(E29, sim_renta!$A$2:$W$11, 23, 0), ""), _xlpm.sub, IF(F29<>0, VLOOKUP(F29, sim_sub!$A$2:$BF$11, 58, 0), ""), _xlpm.sgas, IF(G29<>0, VLOOKUP(G29, sim_sgas!$A$1:$GA$11, 183, 0), ""), _xlpm.lista, _xlfn.TEXTJOIN(", ", TRUE, _xlpm.itbis, _xlpm.renta, _xlpm.sub, _xlpm.sgas), _xlpm.num_comas, LEN(_xlpm.lista) - LEN(SUBSTITUTE(_xlpm.lista, ",", "")), _xlpm.texto_final, IF(_xlpm.num_comas=0, _xlpm.lista, SUBSTITUTE(_xlpm.lista, ", ", " y ", _xlpm.num_comas)), _xlpm.texto_final & IF(H29<>0, " (compensación)", "") ) -> Exentos al 10% y ISR reforma
A30: 29 | B30: 0 | C30: 1 | D30: 1 | E30: 1 | F30: 1 | H30: 0 | I30: =_xlfn.LET( _xlpm.itbis, IF(D30<>0, VLOOKUP(D30, sim_itbis!$A$1:$F$8, 6, 0), ""), _xlpm.renta, IF(E30<>0, VLOOKUP(E30, sim_renta!$A$2:$W$11, 23, 0), ""), _xlpm.sub, IF(F30<>0, VLOOKUP(F30, sim_sub!$A$2:$BF$11, 58, 0), ""), _xlpm.sgas, IF(G30<>0, VLOOKUP(G30, sim_sgas!$A$1:$GA$11, 183, 0), ""), _xlpm.lista, _xlfn.TEXTJOIN(", ", TRUE, _xlpm.itbis, _xlpm.renta, _xlpm.sub, _xlpm.sgas), _xlpm.num_comas, LEN(_xlpm.lista) - LEN(SUBSTITUTE(_xlpm.lista, ",", "")), _xlpm.texto_final, IF(_xlpm.num_comas=0, _xlpm.lista, SUBSTITUTE(_xlpm.lista, ", ", " y ", _xlpm.num_comas)), _xlpm.texto_final & IF(H30<>0, " (compensación)", "") ) -> Exentos al 10%, ISR reforma y Ajuste subsidio eléctrico
A31: 30 | B31: 0 | C31: 1 | D31: 1 | E31: 1 | F31: 1 | H31: 1 | I31: =_xlfn.LET( _xlpm.itbis, IF(D31<>0, VLOOKUP(D31, sim_itbis!$A$1:$F$8, 6, 0), ""), _xlpm.renta, IF(E31<>0, VLOOKUP(E31, sim_renta!$A$2:$W$11, 23, 0), ""), _xlpm.sub, IF(F31<>0, VLOOKUP(F31, sim_sub!$A$2:$BF$11, 58, 0), ""), _xlpm.sgas, IF(G31<>0, VLOOKUP(G31, sim_sgas!$A$1:$GA$11, 183, 0), ""), _xlpm.lista, _xlfn.TEXTJOIN(", ", TRUE, _xlpm.itbis, _xlpm.renta, _xlpm.sub, _xlpm.sgas), _xlpm.num_comas, LEN(_xlpm.lista) - LEN(SUBSTITUTE(_xlpm.lista, ",", "")), _xlpm.texto_final, IF(_xlpm.num_comas=0, _xlpm.lista, SUBSTITUTE(_xlpm.lista, ", ", " y ", _xlpm.num_comas)), _xlpm.texto_final & IF(H31<>0, " (compensación)", "") ) -> Exentos al 10%, ISR reforma y Ajuste subsidio eléctrico (compensación)
A32: 31 | B32: 0 | C32: 2 | D32: 2 | E32: 0 | F32: 0 | H32: 0 | I32: =_xlfn.LET( _xlpm.itbis, IF(D32<>0, VLOOKUP(D32, sim_itbis!$A$1:$F$8, 6, 0), ""), _xlpm.renta, IF(E32<>0, VLOOKUP(E32, sim_renta!$A$2:$W$11, 23, 0), ""), _xlpm.sub, IF(F32<>0, VLOOKUP(F32, sim_sub!$A$2:$BF$11, 58, 0), ""), _xlpm.sgas, IF(G32<>0, VLOOKUP(G32, sim_sgas!$A$1:$GA$11, 183, 0), ""), _xlpm.lista, _xlfn.TEXTJOIN(", ", TRUE, _xlpm.itbis, _xlpm.renta, _xlpm.sub, _xlpm.sgas), _xlpm.num_comas, LEN(_xlpm.lista) - LEN(SUBSTITUTE(_xlpm.lista, ",", "")), _xlpm.texto_final, IF(_xlpm.num_comas=0, _xlpm.lista, SUBSTITUTE(_xlpm.lista, ", ", " y ", _xlpm.num_comas)), _xlpm.texto_final & IF(H32<>0, " (compensación)", "") ) -> ITBIS tasa 16%
A33: 32 | B33: 0 | C33: 2 | D33: 2 | E33: 1 | F33: 0 | H33: 0 | I33: =_xlfn.LET( _xlpm.itbis, IF(D33<>0, VLOOKUP(D33, sim_itbis!$A$1:$F$8, 6, 0), ""), _xlpm.renta, IF(E33<>0, VLOOKUP(E33, sim_renta!$A$2:$W$11, 23, 0), ""), _xlpm.sub, IF(F33<>0, VLOOKUP(F33, sim_sub!$A$2:$BF$11, 58, 0), ""), _xlpm.sgas, IF(G33<>0, VLOOKUP(G33, sim_sgas!$A$1:$GA$11, 183, 0), ""), _xlpm.lista, _xlfn.TEXTJOIN(", ", TRUE, _xlpm.itbis, _xlpm.renta, _xlpm.sub, _xlpm.sgas), _xlpm.num_comas, LEN(_xlpm.lista) - LEN(SUBSTITUTE(_xlpm.lista, ",", "")), _xlpm.texto_final, IF(_xlpm.num_comas=0, _xlpm.lista, SUBSTITUTE(_xlpm.lista, ", ", " y ", _xlpm.num_comas)), _xlpm.texto_final & IF(H33<>0, " (compensación)", "") ) -> ITBIS tasa 16% y ISR reforma
A34: 33 | B34: 0 | C34: 2 | D34: 2 | E34: 1 | F34: 1 | H34: 0 | I34: =_xlfn.LET( _xlpm.itbis, IF(D34<>0, VLOOKUP(D34, sim_itbis!$A$1:$F$8, 6, 0), ""), _xlpm.renta, IF(E34<>0, VLOOKUP(E34, sim_renta!$A$2:$W$11, 23, 0), ""), _xlpm.sub, IF(F34<>0, VLOOKUP(F34, sim_sub!$A$2:$BF$11, 58, 0), ""), _xlpm.sgas, IF(G34<>0, VLOOKUP(G34, sim_sgas!$A$1:$GA$11, 183, 0), ""), _xlpm.lista, _xlfn.TEXTJOIN(", ", TRUE, _xlpm.itbis, _xlpm.renta, _xlpm.sub, _xlpm.sgas), _xlpm.num_comas, LEN(_xlpm.lista) - LEN(SUBSTITUTE(_xlpm.lista, ",", "")), _xlpm.texto_final, IF(_xlpm.num_comas=0, _xlpm.lista, SUBSTITUTE(_xlpm.lista, ", ", " y ", _xlpm.num_comas)), _xlpm.texto_final & IF(H34<>0, " (compensación)", "") ) -> ITBIS tasa 16% , ISR reforma y Ajuste subsidio eléctrico
A35: 34 | B35: 0 | C35: 2 | D35: 2 | E35: 1 | F35: 1 | H35: 1 | I35: =_xlfn.LET( _xlpm.itbis, IF(D35<>0, VLOOKUP(D35, sim_itbis!$A$1:$F$8, 6, 0), ""), _xlpm.renta, IF(E35<>0, VLOOKUP(E35, sim_renta!$A$2:$W$11, 23, 0), ""), _xlpm.sub, IF(F35<>0, VLOOKUP(F35, sim_sub!$A$2:$BF$11, 58, 0), ""), _xlpm.sgas, IF(G35<>0, VLOOKUP(G35, sim_sgas!$A$1:$GA$11, 183, 0), ""), _xlpm.lista, _xlfn.TEXTJOIN(", ", TRUE, _xlpm.itbis, _xlpm.renta, _xlpm.sub, _xlpm.sgas), _xlpm.num_comas, LEN(_xlpm.lista) - LEN(SUBSTITUTE(_xlpm.lista, ",", "")), _xlpm.texto_final, IF(_xlpm.num_comas=0, _xlpm.lista, SUBSTITUTE(_xlpm.lista, ", ", " y ", _xlpm.num_comas)), _xlpm.texto_final & IF(H35<>0, " (compensación)", "") ) -> ITBIS tasa 16% , ISR reforma y Ajuste subsidio eléctrico (compensación)
A36: 35 | B36: 0 | C36: 11 | D36: 0 | E36: 1 | F36: 0 | H36: 0 | I36: =_xlfn.LET( _xlpm.itbis, IF(D36<>0, VLOOKUP(D36, sim_itbis!$A$1:$F$8, 6, 0), ""), _xlpm.renta, IF(E36<>0, VLOOKUP(E36, sim_renta!$A$2:$W$11, 23, 0), ""), _xlpm.sub, IF(F36<>0, VLOOKUP(F36, sim_sub!$A$2:$BF$11, 58, 0), ""), _xlpm.sgas, IF(G36<>0, VLOOKUP(G36, sim_sgas!$A$1:$GA$11, 183, 0), ""), _xlpm.lista, _xlfn.TEXTJOIN(", ", TRUE, _xlpm.itbis, _xlpm.renta, _xlpm.sub, _xlpm.sgas), _xlpm.num_comas, LEN(_xlpm.lista) - LEN(SUBSTITUTE(_xlpm.lista, ",", "")), _xlpm.texto_final, IF(_xlpm.num_comas=0, _xlpm.lista, SUBSTITUTE(_xlpm.lista, ", ", " y ", _xlpm.num_comas)), _xlpm.texto_final & IF(H36<>0, " (compensación)", "") ) -> ISR reforma
A37: 36 | B37: 0 | C37: 11 | D37: 0 | E37: 1 | F37: 0 | H37: 1 | I37: =_xlfn.LET( _xlpm.itbis, IF(D37<>0, VLOOKUP(D37, sim_itbis!$A$1:$F$8, 6, 0), ""), _xlpm.renta, IF(E37<>0, VLOOKUP(E37, sim_renta!$A$2:$W$11, 23, 0), ""), _xlpm.sub, IF(F37<>0, VLOOKUP(F37, sim_sub!$A$2:$BF$11, 58, 0), ""), _xlpm.sgas, IF(G37<>0, VLOOKUP(G37, sim_sgas!$A$1:$GA$11, 183, 0), ""), _xlpm.lista, _xlfn.TEXTJOIN(", ", TRUE, _xlpm.itbis, _xlpm.renta, _xlpm.sub, _xlpm.sgas), _xlpm.num_comas, LEN(_xlpm.lista) - LEN(SUBSTITUTE(_xlpm.lista, ",", "")), _xlpm.texto_final, IF(_xlpm.num_comas=0, _xlpm.lista, SUBSTITUTE(_xlpm.lista, ", ", " y ", _xlpm.num_comas)), _xlpm.texto_final & IF(H37<>0, " (compensación)", "") ) -> ISR reforma (compensación)
A38: 37 | B38: 0 | C38: 21 | D38: 0 | E38: 0 | F38: 1 | H38: 0 | I38: =_xlfn.LET( _xlpm.itbis, IF(D38<>0, VLOOKUP(D38, sim_itbis!$A$1:$F$8, 6, 0), ""), _xlpm.renta, IF(E38<>0, VLOOKUP(E38, sim_renta!$A$2:$W$11, 23, 0), ""), _xlpm.sub, IF(F38<>0, VLOOKUP(F38, sim_sub!$A$2:$BF$11, 58, 0), ""), _xlpm.sgas, IF(G38<>0, VLOOKUP(G38, sim_sgas!$A$1:$GA$11, 183, 0), ""), _xlpm.lista, _xlfn.TEXTJOIN(", ", TRUE, _xlpm.itbis, _xlpm.renta, _xlpm.sub, _xlpm.sgas), _xlpm.num_comas, LEN(_xlpm.lista) - LEN(SUBSTITUTE(_xlpm.lista, ",", "")), _xlpm.texto_final, IF(_xlpm.num_comas=0, _xlpm.lista, SUBSTITUTE(_xlpm.lista, ", ", " y ", _xlpm.num_comas)), _xlpm.texto_final & IF(H38<>0, " (compensación)", "") ) -> Ajuste subsidio eléctrico

Sheet sim_itbis
A1: sim_itbis | B1: activo | C1: tasa_itbis | D1: exentos_gravados | E1: uniforma_tasa | F1: nom_itbis | G1: base_formal
A2: 0 | B2: 1 | C2: 18 | D2: 0 | E2: 0 | F2: Base | G2: 4
A3: 1 | B3: 1 | C3: 18 | D3: 1 | E3: 1 | F3: Exentos al 10% | G3: 4
A4: 2 | B4: 1 | C4: 16 | D4: 1 | E4: 1 | F4: ITBIS tasa 16% | G4: 4
A5: 3 | B5: 0 | C5: 16 | D5: 1 | E5: 1 | F5: ITBIS tasa única 16 | G5: 4
A6: 4 | B6: 0 | C6: 16 | D6: 1 | E6: 1 | F6: ITBIS 16 (menos 11 productos) | G6: 4
A7: 5 | B7: 0 | C7: 16 | D7: 1 | E7: 1
A8: 6 | B8: 0

Sheet itbis_sim
A1: cod_variedad | B1: cod_articulo | C1: variedad | D1: itbis_alt1 | E1: itbis_alt2 | F1: itbis_alt3 | G1: itbis_alt4 | H1: itbis_alt5
A2: 1 | B2: 11111 | C2: Pan de agua | D2: 0 | E2: 16 | F2: 0 | G2: 16 | H2: 0
A3: 2 | B3: 11111 | C3: Pan sobado | D3: 0 | E3: 16 | F3: 0 | G3: 16 | H3: 0
A4: 3 | B4: 11111 | C4: Pan de leche | D4: 0 | E4: 16 | F4: 0 | G4: 16 | H4: 0
A5: 5 | B5: 11111 | C5: Pan de mantequilla | D5: 0 | E5: 16 | F5: 0 | G5: 16 | H5: 0
A6: 6 | B6: 11111 | C6: Pan baguette blanco | D6: 0 | E6: 16 | F6: 0 | G6: 16 | H6: 0
A7: 7 | B7: 11111 | C7: Pan baguette integral | D7: 0 | E7: 16 | F7: 0 | G7: 16 | H7: 0
A8: 8 | B8: 11111 | C8: Pan camarón | D8: 0 | E8: 16 | F8: 0 | G8: 16 | H8: 0
A9: 9 | B9: 11111 | C9: Pan integral | D9: 0 | E9: 16 | F9: 0 | G9: 16 | H9: 0
A10: 10 | B10: 11111 | C10: Pan telera | D10: 0 | E10: 16 | F10: 0 | G10: 16 | H10: 0
A11: 12 | B11: 11111 | C11: Pan de pita | D11: 0 | E11: 16 | F11: 0 | G11: 16 | H11: 0
A12: 13 | B12: 11111 | C12: Pan de sándwich rebanado blanco | D12: 0 | E12: 16 | F12: 0 | G12: 16 | H12: 0
A13: 14 | B13: 11111 | C13: Pan de sándwich rebanado integral | D13: 0 | E13: 16 | F13: 0 | G13: 16 | H13: 0
... A23: 7837 | B23: 11111 | C23: Pan de puerro y cebolla | D23: 0 | E23: 16 | F23: 0 | G23: 16 | H23: 0
A24: 35 | B24: 11113 | C24: Violados | D24: 10 | F24: 10
A25: 8246 | B25: 11111 | C25: Pan de anís | D25: 0 | E25: 16 | F25: 0 | G25: 16 | H25: 0
A26: 17 | B26: 11112 | C26: Galletas con ajonjolí | D26: 10 | E26: 16 | F26: 10 | G26: 16
A27: 18 | B27: 11112 | C27: Galletas de harina / Galleta de manteca | D27: 10 | E27: 16 | F27: 10 | G27: 16
A28: 20 | B28: 11112 | C28: Galletas dulces | D28: 10 | E28: 16 | F28: 10 | G28: 16
A29: 21 | B29: 11112 | C29: Galletas integrales | D29: 10 | E29: 16 | F29: 10 | G29: 16
A30: 22 | B30: 11112 | C30: Galletas María | D30: 10 | E30: 16 | F30: 10 | G30: 16
A31: 23 | B31: 11112 | C31: Galletas saladas | D31: 10 | E31: 16 | F31: 10 | G31: 16
A32: 24 | B32: 11112 | C32: Galletas de Avena / Granola | D32: 10 | E32: 16 | F32: 10 | G32: 16
A33: 3498 | B33: 11112 | C33: Galletas de huevo | D33: 10 | E33: 16 | F33: 10 | G33: 16
A34: 4148 | B34: 11112 | C34: Galletas de ajo | D34: 10 | E34: 16 | F34: 10 | G34: 16
A35: 4149 | B35: 11112 | C35: Galletas rellenas de queso | D35: 10 | E35: 16 | F35: 10 | G35: 16
A36: 4 | B36: 11113 | C36: Pan de maíz entero | D36: 10 | E36: 16 | F36: 10 | G36: 16
A37: 29 | B37: 11113 | C37: Polvorones | D37: 10 | E37: 16 | F37: 10 | G37: 16
... A47: 2549 | B47: 11113 | C47: Quipe de res | D47: 10 | E47: 16 | F47: 10 | G47: 16
A48: 2632 | B48: 11113 | C48: Yaniqueques | D48: 10 | E48: 16 | F48: 10 | G48: 16 | H48: 16
A49: 2881 | B49: 11113 | C49: Pan de yautía | D49: 10 | E49: 16 | F49: 10 | G49: 16
A50: 3530 | B50: 11113 | C50: Pastelito de res | D50: 10 | E50: 16 | F50: 10 | G50: 16
A51: 3531 | B51: 11113 | C51: Pastelito de queso amarillo | D51: 10 | E51: 16 | F51: 10 | G51: 16
A52: 3533 | B52: 11113 | C52: Pastelito de jamón y queso | D52: 10 | E52: 16 | F52: 10 | G52: 16
A53: 3534 | B53: 11113 | C53: Pastelito de queso, pollo y maíz | D53: 10 | E53: 16 | F53: 10 | G53: 16
A54: 3539 | B54: 11113 | C54: Quipes de camarón | D54: 10 | E54: 16 | F54: 10 | G54: 16
A55: 3541 | B55: 11113 | C55: Croquetas de pollo y jamón | D55: 10 | E55: 16 | F55: 10 | G55: 16
A56: 3543 | B56: 11113 | C56: Croquetas de chorizo | D56: 10 | E56: 16 | F56: 10 | G56: 16
A57: 4913 | B57: 11113 | C57: Arepa dulce | D57: 10 | E57: 16 | F57: 10 | G57: 16
A58: 4914 | B58: 11113 | C58: Arepa salada | D58: 10 | E58: 16 | F58: 10 | G58: 16
...

Sheet itbis_base
A1: COD_GRUPO | B1: DES_GRUPO | C1: COD_SUBGRUPO | D1: DES_SUBGRUPO | E1: COD_CLASE | F1: DES_CLASE | G1: COD_SUBCLASE | H1: DES_SUBCLASE | I1: COD_ARTICULO | J1: DES_ARTICULO | K1: ID_VARIEDAD | L1: DES_VARIEDAD | M1: tasa | N1: grupo | O1: gravado | P1: cod_arancelario | Q1: codigo_mip | R1: sector2
A2: 1 | B2: ALIMENTOS Y BEBIDAS NO ALCOHOLICAS | C2: 11 | D2: ALIMENTOS | E2: 111 | F2: Pan y cereales (ND) | G2: 1111 | H2: Productos de Panadería | I2: 11111 | J2: Pan | K2: 1 | L2: Pan de agua | M2: 0 | N2: exentos | O2: 0 | P2: 19 05 | Q2: 4 | R2: 8
A3: 1 | B3: ALIMENTOS Y BEBIDAS NO ALCOHOLICAS | C3: 11 | D3: ALIMENTOS | E3: 111 | F3: Pan y cereales (ND) | G3: 1111 | H3: Productos de Panadería | I3: 11111 | J3: Pan | K3: 2 | L3: Pan sobado | M3: 0 | N3: exentos | O3: 0 | P3: 19 05 | Q3: 4 | R3: 8
A4: 1 | B4: ALIMENTOS Y BEBIDAS NO ALCOHOLICAS | C4: 11 | D4: ALIMENTOS | E4: 111 | F4: Pan y cereales (ND) | G4: 1111 | H4: Productos de Panadería | I4: 11111 | J4: Pan | K4: 3 | L4: Pan de leche | M4: 0 | N4: exentos | O4: 0 | P4: 19 05 | Q4: 4 | R4: 8
A5: 1 | B5: ALIMENTOS Y BEBIDAS NO ALCOHOLICAS | C5: 11 | D5: ALIMENTOS | E5: 111 | F5: Pan y cereales (ND) | G5: 1111 | H5: Productos de Panadería | I5: 11113 | J5: Otros productos de panadería | K5: 4 | L5: Pan de maíz entero | M5: 0 | N5: exentos | O5: 0 | P5: 19 05 | Q5: 4 | R5: 8
A6: 1 | B6: ALIMENTOS Y BEBIDAS NO ALCOHOLICAS | C6: 11 | D6: ALIMENTOS | E6: 111 | F6: Pan y cereales (ND) | G6: 1111 | H6: Productos de Panadería | I6: 11111 | J6: Pan | K6: 5 | L6: Pan de mantequilla | M6: 0 | N6: exentos | O6: 0 | P6: 19 05 | Q6: 4 | R6: 8
A7: 1 | B7: ALIMENTOS Y BEBIDAS NO ALCOHOLICAS | C7: 11 | D7: ALIMENTOS | E7: 111 | F7: Pan y cereales (ND) | G7: 1111 | H7: Productos de Panadería | I7: 11111 | J7: Pan | K7: 6 | L7: Pan baguette blanco | M7: 0 | N7: exentos | O7: 0 | P7: 19 05 | Q7: 4 | R7: 8
A8: 1 | B8: ALIMENTOS Y BEBIDAS NO ALCOHOLICAS | C8: 11 | D8: ALIMENTOS | E8: 111 | F8: Pan y cereales (ND) | G8: 1111 | H8: Productos de Panadería | I8: 11111 | J8: Pan | K8: 7 | L8: Pan baguette integral | M8: 0 | N8: exentos | O8: 0 | P8: 19 05 | Q8: 4 | R8: 8
A9: 1 | B9: ALIMENTOS Y BEBIDAS NO ALCOHOLICAS | C9: 11 | D9: ALIMENTOS | E9: 111 | F9: Pan y cereales (ND) | G9: 1111 | H9: Productos de Panadería | I9: 11111 | J9: Pan | K9: 8 | L9: Pan camarón | M9: 0 | N9: exentos | O9: 0 | P9: 19 05 | Q9: 4 | R9: 8
A10: 1 | B10: ALIMENTOS Y BEBIDAS NO ALCOHOLICAS | C10: 11 | D10: ALIMENTOS | E10: 111 | F10: Pan y cereales (ND) | G10: 1111 | H10: Productos de Panadería | I10: 11111 | J10: Pan | K10: 9 | L10: Pan integral | M10: 0 | N10: exentos | O10: 0 | P10: 19 05 | Q10: 4 | R10: 8
A11: 1 | B11: ALIMENTOS Y BEBIDAS NO ALCOHOLICAS | C11: 11 | D11: ALIMENTOS | E11: 111 | F11: Pan y cereales (ND) | G11: 1111 | H11: Productos de Panadería | I11: 11111 | J11: Pan | K11: 10 | L11: Pan telera | M11: 0 | N11: exentos | O11: 0 | P11: 19 05 | Q11: 4 | R11: 8
A12: 1 | B12: ALIMENTOS Y BEBIDAS NO ALCOHOLICAS | C12: 11 | D12: ALIMENTOS | E12: 111 | F12: Pan y cereales (ND) | G12: 1111 | H12: Productos de Panadería | I12: 11111 | J12: Pan | K12: 12 | L12: Pan de pita | M12: 0 | N12: exentos | O12: 0 | P12: 19 05 | Q12: 4 | R12: 8
A13: 1 | B13: ALIMENTOS Y BEBIDAS NO ALCOHOLICAS | C13: 11 | D13: ALIMENTOS | E13: 111 | F13: Pan y cereales (ND) | G13: 1111 | H13: Productos de Panadería | I13: 11111 | J13: Pan | K13: 13 | L13: Pan de sándwich rebanado blanco | M13: 0 | N13: exentos | O13: 0 | P13: 19 05 | Q13: 4 | R13: 8
... A15: 1 | B15: ALIMENTOS Y BEBIDAS NO ALCOHOLICAS | C15: 11 | D15: ALIMENTOS | E15: 111 | F15: Pan y cereales (ND) | G15: 1111 | H15: Productos de Panadería | I15: 11111 | J15: Pan | K15: 15 | L15: Pan de hot dog | M15: 0 | N15: exentos | O15: 0 | P15: 19 05 | Q15: 4 | R15: 8
A16: 1 | B16: ALIMENTOS Y BEBIDAS NO ALCOHOLICAS | C16: 11 | D16: ALIMENTOS | E16: 111 | F16: Pan y cereales (ND) | G16: 1111 | H16: Productos de Panadería | I16: 11112 | J16: Galletas y masas secas | K16: 17 | L16: Galletas con ajonjolí | M16: 0 | N16: exentos | O16: 0 | Q16: 4 | R16: 8
A17: 1 | B17: ALIMENTOS Y BEBIDAS NO ALCOHOLICAS | C17: 11 | D17: ALIMENTOS | E17: 111 | F17: Pan y cereales (ND) | G17: 1111 | H17: Productos de Panadería | I17: 11112 | J17: Galletas y masas secas | K17: 18 | L17: Galletas de harina / Galleta de manteca | M17: 0 | N17: exentos | O17: 0 | Q17: 4 | R17: 8
A18: 1 | B18: ALIMENTOS Y BEBIDAS NO ALCOHOLICAS | C18: 11 | D18: ALIMENTOS | E18: 111 | F18: Pan y cereales (ND) | G18: 1111 | H18: Productos de Panadería | I18: 11112 | J18: Galletas y masas secas | K18: 19 | L18: Galletas de soda | M18: 18 | N18: normal | O18: 1 | Q18: 4 | R18: 7
A19: 1 | B19: ALIMENTOS Y BEBIDAS NO ALCOHOLICAS | C19: 11 | D19: ALIMENTOS | E19: 111 | F19: Pan y cereales (ND) | G19: 1111 | H19: Productos de Panadería | I19: 11112 | J19: Galletas y masas secas | K19: 20 | L19: Galletas dulces | M19: 0 | N19: exentos | O19: 0 | Q19: 4 | R19: 8
A20: 1 | B20: ALIMENTOS Y BEBIDAS NO ALCOHOLICAS | C20: 11 | D20: ALIMENTOS | E20: 111 | F20: Pan y cereales (ND) | G20: 1111 | H20: Productos de Panadería | I20: 11112 | J20: Galletas y masas secas | K20: 21 | L20: Galletas integrales | M20: 0 | N20: exentos | O20: 0 | Q20: 4 | R20: 8
A21: 1 | B21: ALIMENTOS Y BEBIDAS NO ALCOHOLICAS | C21: 11 | D21: ALIMENTOS | E21: 111 | F21: Pan y cereales (ND) | G21: 1111 | H21: Productos de Panadería | I21: 11112 | J21: Galletas y masas secas | K21: 22 | L21: Galletas María | M21: 0 | N21: exentos | O21: 0 | Q21: 4 | R21: 8
A22: 1 | B22: ALIMENTOS Y BEBIDAS NO ALCOHOLICAS | C22: 11 | D22: ALIMENTOS | E22: 111 | F22: Pan y cereales (ND) | G22: 1111 | H22: Productos de Panadería | I22: 11112 | J22: Galletas y masas secas | K22: 23 | L22: Galletas saladas | M22: 0 | N22: exentos | O22: 0 | Q22: 4 | R22: 8
A23: 1 | B23: ALIMENTOS Y BEBIDAS NO ALCOHOLICAS | C23: 11 | D23: ALIMENTOS | E23: 111 | F23: Pan y cereales (ND) | G23: 1111 | H23: Productos de Panadería | I23: 11112 | J23: Galletas y masas secas | K23: 24 | L23: Galletas de Avena / Granola | M23: 0 | N23: exentos | O23: 0 | Q23: 4 | R23: 8
A24: 1 | B24: ALIMENTOS Y BEBIDAS NO ALCOHOLICAS | C24: 11 | D24: ALIMENTOS | E24: 111 | F24: Pan y cereales (ND) | G24: 1111 | H24: Productos de Panadería | I24: 11113 | J24: Otros productos de panadería | K24: 29 | L24: Polvorones | M24: 0 | N24: exentos | O24: 0 | Q24: 4 | R24: 8
A25: 1 | B25: ALIMENTOS Y BEBIDAS NO ALCOHOLICAS | C25: 11 | D25: ALIMENTOS | E25: 111 | F25: Pan y cereales (ND) | G25: 1111 | H25: Productos de Panadería | I25: 11113 | J25: Otros productos de panadería | K25: 32 | L25: Palomitas de maíz para microondas | M25: 18 | N25: normal | O25: 1 | Q25: 4 | R25: 7
A26: 1 | B26: ALIMENTOS Y BEBIDAS NO ALCOHOLICAS | C26: 11 | D26: ALIMENTOS | E26: 111 | F26: Pan y cereales (ND) | G26: 1111 | H26: Productos de Panadería | I26: 11113 | J26: Otros productos de panadería | K26: 35 | L26: Violados | M26: 0 | N26: exentos | O26: 0 | Q26: 4 | R26: 8
A27: 1 | B27: ALIMENTOS Y BEBIDAS NO ALCOHOLICAS | C27: 11 | D27: ALIMENTOS | E27: 111 | F27: Pan y cereales (ND) | G27: 1111 | H27: Productos de Panadería | I27: 11113 | J27: Otros productos de panadería | K27: 38 | L27: Dulces de harina rellenos | M27: 18 | N27: normal | O27: 1 | Q27: 4 | R27: 7
... A38: 1 | B38: ALIMENTOS Y BEBIDAS NO ALCOHOLICAS | C38: 11 | D38: ALIMENTOS | E38: 111 | F38: Pan y cereales (ND) | G38: 1111 | H38: Productos de Panadería | I38: 11113 | J38: Otros productos de panadería | K38: 53 | L38: Tortilla de maíz (para tacos) | M38: 0 | N38: exentos | O38: 0 | Q38: 4 | R38: 8
A39: 1 | B39: ALIMENTOS Y BEBIDAS NO ALCOHOLICAS | C39: 11 | D39: ALIMENTOS | E39: 111 | F39: Pan y cereales (ND) | G39: 1112 | H39: Harinas | I39: 11121 | J39: Harinas y derivados | K39: 56 | L39: Harinas de maíz | M39: 18 | N39: normal | O39: 1 | P39: 11 02 | Q39: 4 | R39: 7
A40: 1 | B40: ALIMENTOS Y BEBIDAS NO ALCOHOLICAS | C40: 11 | D40: ALIMENTOS | E40: 111 | F40: Pan y cereales (ND) | G40: 1112 | H40: Harinas | I40: 11121 | J40: Harinas y derivados | K40: 57 | L40: Maicena (fécula de maíz) /Maicera (harina de maíz procesada) | M40: 0 | N40: exentos | O40: 0 | Q40: 4 | R40: 8
A41: 1 | B41: ALIMENTOS Y BEBIDAS NO ALCOHOLICAS | C41: 11 | D41: ALIMENTOS | E41: 111 | F41: Pan y cereales (ND) | G41: 1112 | H41: Harinas | I41: 11121 | J41: Harinas y derivados | K41: 58 | L41: Harina de trigo | M41: 0 | N41: exentos | O41: 0 | P41: 11 01 | Q41: 4 | R41: 8
A42: 1 | B42: ALIMENTOS Y BEBIDAS NO ALCOHOLICAS | C42: 11 | D42: ALIMENTOS | E42: 111 | F42: Pan y cereales (ND) | G42: 1112 | H42: Harinas | I42: 11121 | J42: Harinas y derivados | K42: 59 | L42: Harina de negrito (fécula de trigo) | M42: 18 | N42: normal | O42: 1 | P42: 11 01 | Q42: 4 | R42: 7
A43: 1 | B43: ALIMENTOS Y BEBIDAS NO ALCOHOLICAS | C43: 11 | D43: ALIMENTOS | E43: 111 | F43: Pan y cereales (ND) | G43: 1112 | H43: Harinas | I43: 11121 | J43: Harinas y derivados | K43: 60 | L43: Harina de panqueques | M43: 18 | N43: normal | O43: 1 | P43: 11 01 | Q43: 4 | R43: 7
A44: 1 | B44: ALIMENTOS Y BEBIDAS NO ALCOHOLICAS | C44: 11 | D44: ALIMENTOS | E44: 111 | F44: Pan y cereales (ND) | G44: 1112 | H44: Harinas | I44: 11121 | J44: Harinas y derivados | K44: 61 | L44: Harina de plátano | M44: 18 | N44: normal | O44: 1 | Q44: 4 | R44: 7
A45: 1 | B45: ALIMENTOS Y BEBIDAS NO ALCOHOLICAS | C45: 11 | D45: ALIMENTOS | E45: 111 | F45: Pan y cereales (ND) | G45: 1112 | H45: Harinas | I45: 11121 | J45: Harinas y derivados | K45: 62 | L45: Sémola de maíz | M45: 0 | N45: exentos | O45: 0 | P45: 11 03 | Q45: 4 | R45: 8
A46: 1 | B46: ALIMENTOS Y BEBIDAS NO ALCOHOLICAS | C46: 11 | D46: ALIMENTOS | E46: 111 | F46: Pan y cereales (ND) | G46: 1113 | H46: Cereales | I46: 11131 | J46: Arroz | K46: 65 | L46: Arroz súper-selecto o premium | M46: 0 | N46: exentos | O46: 0 | P46: 10 06 | Q46: 4 | R46: 8
A47: 1 | B47: ALIMENTOS Y BEBIDAS NO ALCOHOLICAS | C47: 11 | D47: ALIMENTOS | E47: 111 | F47: Pan y cereales (ND) | G47: 1113 | H47: Cereales | I47: 11131 | J47: Arroz | K47: 66 | L47: Arroz selecto | M47: 0 | N47: exentos | O47: 0 | P47: 10 06 | Q47: 4 | R47: 8
A48: 1 | B48: ALIMENTOS Y BEBIDAS NO ALCOHOLICAS | C48: 11 | D48: ALIMENTOS | E48: 111 | F48: Pan y cereales (ND) | G48: 1113 | H48: Cereales | I48: 11131 | J48: Arroz | K48: 67 | L48: Arroz corriente | M48: 0 | N48: exentos | O48: 0 | P48: 10 06 | Q48: 4 | R48: 8
A49: 1 | B49: ALIMENTOS Y BEBIDAS NO ALCOHOLICAS | C49: 11 | D49: ALIMENTOS | E49: 111 | F49: Pan y cereales (ND) | G49: 1113 | H49: Cereales | I49: 11131 | J49: Arroz | K49: 69 | L49: Arroz integral | M49: 0 | N49: exentos | O49: 0 | P49: 10 06 | Q49: 4 | R49: 8
A50: 1 | B50: ALIMENTOS Y BEBIDAS NO ALCOHOLICAS | C50: 11 | D50: ALIMENTOS | E50: 111 | F50: Pan y cereales (ND) | G50: 1113 | H50: Cereales | I50: 11132 | J50: Otros cereales y derivados | K50: 71 | L50: Avena en hojuela o entera | M50: 0 | N50: exentos | O50: 0 | Q50: 4 | R50: 8
A51: 1 | B51: ALIMENTOS Y BEBIDAS NO ALCOHOLICAS | C51: 11 | D51: ALIMENTOS | E51: 111 | F51: Pan y cereales (ND) | G51: 1113 | H51: Cereales | I51: 11132 | J51: Otros cereales y derivados | K51: 72 | L51: Avena molida saborizada (Frescavena y otras) | M51: 18 | N51: normal | O51: 1 | Q51: 4 | R51: 7
...

Sheet sim_renta
A1: sim_inc | B1: activo | C1: tramo1 | D1: tramo2 | E1: tramo3 | F1: tramo4 | G1: tramo5 | H1: tramo6 | I1: base1 | J1: base2 | K1: base3 | L1: base4 | M1: base5 | N1: base6 | O1: tasa1 | P1: tasa2 | Q1: tasa3 | R1: tasa4 | S1: tasa5 | T1: tasa6 | U1: educ_share | V1: educ_limit | W1: nom_renta
A2: 0 | B2: 1 | C2: 0 | D2: 416220 | E2: 624329 | F2: 867123 | I2: 0 | J2: =(D2-C2)*O2+I2 -> 0 | K2: =ROUND((E2-D2)*P2+J2,2) -> 31216.35 | L2: =ROUND((F2-E2)*Q2+K2,2) -> 79775.15 | O2: 0 | P2: 0.15 | Q2: 0.2 | R2: 0.25 | U2: 0.1 | V2: 0.25
A3: 1 | B3: 1 | C3: 0 | D3: =39900*12 -> 478800 | E3: =E2 -> 624329 | F3: =F2 -> 867123 | G3: =400000*12 -> 4800000 | I3: 0 | J3: =(D3-C3)*O3+I3 -> 0 | K3: =(E3-D3)*P3+J3 -> 21829.35 | L3: =(F3-E3)*Q3+K3 -> 70388.15 | M3: =(G3-F3)*R3+L3 -> 1053607.4 | O3: 0 | P3: 0.15 | Q3: 0.2 | R3: 0.25 | S3: 0.27 | U3: 0.1 | V3: 0.3 | W3: ISR reforma
A4: 2 | B4: 0
A5: 3 | B5: 0
A6: 4 | B6: 0
A7: 5 | B7: 0
A8: 6 | B8: 0
A9: 7 | B9: 0
A10: 8 | B10: 0
A11: 9 | B11: 0

Sheet sim_sub
A1: sim_sub | B1: activo | C1: block1 | D1: block2 | E1: block3 | F1: block4 | G1: block5 | H1: block6 | I1: block7 | J1: bsur1 | K1: bsur2 | L1: bsur3 | M1: bsur4 | N1: bsur5 | O1: bsur6 | P1: bsur7 | Q1: bnorte1 | R1: bnorte2 | S1: bnorte3 | T1: bnorte4 | U1: bnorte5 | V1: bnorte6 | W1: bnorte7 | X1: beste1 | Y1: beste2 | Z1: beste3 | AA1: beste4 | AB1: beste5 | AC1: beste6 | AD1: beste7 | AE1: otsur | AF1: tsur1 | AG1: tsur2 | AH1: tsur3 | AI1: tsur4 | AJ1: tsur5 | AK1: tsur6 | AL1: tsur7 | AM1: otnorte | AN1: tnorte1 | AO1: tnorte2 | AP1: tnorte3 | AQ1: tnorte4 | AR1: tnorte5 | AS1: tnorte6 | AT1: tnorte7 | AU1: oteste | AV1: teste1 | AW1: teste2 | AX1: teste3 | AY1: teste4 | AZ1: teste5 | BA1: teste6 | BB1: teste7 | BC1: costsur | BD1: costnorte | BE1: costeste | BF1: nom_subsidio
A2: 0 | B2: 1 | C2: 0 | D2: 100 | E2: 200 | F2: 300 | G2: 700 | J2: 42.1 | K2: 128.59 | L2: 128.59 | M2: 128.59 | N2: 128.59 | Q2: 40.33 | R2: 126.81 | S2: 126.81 | T2: 126.81 | U2: 126.81 | X2: 41.34 | Y2: 127.83 | Z2: 127.83 | AA2: 127.83 | AB2: 127.83 | AE2: 6.05 | AF2: 6.05 | AG2: 6.05 | AH2: 8.59 | AI2: 12.89 | AJ2: 13.09 | AM2: 5.97 | AN2: 5.97 | AO2: 5.97 | AP2: 8.51 | AQ2: 13.83 | AR2: 14.04 | AU2: 6.17 | AV2: 6.17 | AW2: 6.17 | AX2: 8.71 | AY2: 13.04 | AZ2: 13.26 | BC2: =(15.35/100)*59.4086 -> 9.1192201 | BD2: =(15.69/100)*59.4086 -> 9.3212093 | BE2: =(14.37/100)*59.4086 -> 8.5370158
A3: 1 | B3: 1 | C3: 0 | D3: 100 | E3: 200 | F3: 300 | G3: 700 | J3: 42.1 | K3: 128.59 | L3: 128.59 | M3: 128.59 | N3: 128.59 | Q3: 40.33 | R3: 126.81 | S3: 126.81 | T3: 126.81 | U3: 126.81 | X3: 41.34 | Y3: 127.83 | Z3: 127.83 | AA3: 127.83 | AB3: 127.83 | AE3: 6.05 | AF3: 6.9 | AG3: 6.9 | AH3: 9.11 | AI3: 14.69 | AJ3: 14.92 | AM3: 5.97 | AN3: 6.81 | AO3: 6.81 | AP3: 9.02 | AQ3: 15.77 | AR3: 16.01 | AU3: 6.17 | AV3: 7.03 | AW3: 7.03 | AX3: 9.23 | AY3: 14.87 | AZ3: 15.12 | BC3: =(15.35/100)*59.4086 -> 9.1192201 | BD3: =(15.69/100)*59.4086 -> 9.3212093 | BE3: =(14.37/100)*59.4086 -> 8.5370158 | BF3: Ajuste subsidio eléctrico
A4: 2 | B4: 1 | C4: 0 | D4: 100 | E4: 200 | F4: 300 | G4: 700 | J4: 42.1 | K4: 128.59 | L4: 128.59 | M4: 128.59 | N4: 128.59 | Q4: 126.81 | R4: 126.81 | S4: 126.81 | T4: 126.81 | U4: 126.81 | X4: 41.34 | Y4: 127.83 | Z4: 127.83 | AA4: 127.83 | AB4: 127.83 | AE4: 6.05 | AF4: 6.05 | AG4: 6.05 | AH4: 8.59 | AI4: 12.89 | AJ4: 13.09 | AM4: 9.5 | AN4: 9.5 | AO4: 9.5 | AP4: 9.5 | AQ4: 13.83 | AR4: 14.04 | AU4: 6.17 | AV4: 6.17 | AW4: 6.17 | AX4: 8.71 | AY4: 13.04 | AZ4: 13.26 | BC4: =(15.35/100)*59.4086 -> 9.1192201 | BD4: =(15.69/100)*59.4086 -> 9.3212093 | BE4: =(14.37/100)*59.4086 -> 8.5370158 | BF4: Sin subsidio
A5: 3 | B5: 0
A6: 4 | B6: 0
A7: 5 | B7: 0
A8: 6 | B8: 0
A9: 7 | B9: 0
A10: 8 | B10: 0
A11: 9 | B11: 0

Sheet sim_sgas
A1: sim_sgas | B1: activo | C1: m1 | D1: m2 | E1: m3 | F1: m4 | G1: m5 | H1: m6 | I1: m7 | J1: m8 | K1: m9 | L1: m10 | M1: m11 | N1: m12 | O1: gasoil_premium_precio_1 | P1: gasoil_premium_precio_2 | Q1: gasoil_premium_precio_3 | R1: gasoil_premium_precio_4 | S1: gasoil_premium_precio_5 | T1: gasoil_premium_precio_6 | U1: gasoil_premium_precio_7 | V1: gasoil_premium_precio_8 | W1: gasoil_premium_precio_9 | X1: gasoil_premium_precio_10 | Y1: gasoil_premium_precio_11 | Z1: gasoil_premium_precio_12 | AA1: gasoil_regular_precio_1 | AB1: gasoil_regular_precio_2 | AC1: gasoil_regular_precio_3 | AD1: gasoil_regular_precio_4 | AE1: gasoil_regular_precio_5 | AF1: gasoil_regular_precio_6 | AG1: gasoil_regular_precio_7 | AH1: gasoil_regular_precio_8 | AI1: gasoil_regular_precio_9 | AJ1: gasoil_regular_precio_10 | AK1: gasoil_regular_precio_11 | AL1: gasoil_regular_precio_12 | AM1: gasolina_premium_precio_1 | AN1: gasolina_premium_precio_2 | AO1: gasolina_premium_precio_3 | AP1: gasolina_premium_precio_4 | AQ1: gasolina_premium_precio_5 | AR1: gasolina_premium_precio_6 | AS1: gasolina_premium_precio_7 | AT1: gasolina_premium_precio_8 | AU1: gasolina_premium_precio_9 | AV1: gasolina_premium_precio_10 | AW1: gasolina_premium_precio_11 | AX1: gasolina_premium_precio_12 | AY1: gasolina_regular_precio_1 | AZ1: gasolina_regular_precio_2 | BA1: gasolina_regular_precio_3 | BB1: gasolina_regular_precio_4 | BC1: gasolina_regular_precio_5 | BD1: gasolina_regular_precio_6 | BE1: gasolina_regular_precio_7 | BF1: gasolina_regular_precio_8 | BG1: gasolina_regular_precio_9 | BH1: gasolina_regular_precio_10 | BI1: gasolina_regular_precio_11 | BJ1: gasolina_regular_precio_12 | BK1: glp_precio_1 | BL1: glp_precio_2 | BM1: glp_precio_3 | BN1: glp_precio_4 | BO1: glp_precio_5 | BP1: glp_precio_6 | BQ1: glp_precio_7 | BR1: glp_precio_8 | BS1: glp_precio_9 | BT1: glp_precio_10 | BU1: glp_precio_11 | BV1: glp_precio_12 | BW1: gasoil_premium_sub_1 | BX1: gasoil_premium_sub_2 | BY1: gasoil_premium_sub_3 | BZ1: gasoil_premium_sub_4 | CA1: gasoil_premium_sub_5 | CB1: gasoil_premium_sub_6 | CC1: gasoil_premium_sub_7 | CD1: gasoil_premium_sub_8 | CE1: gasoil_premium_sub_9 | CF1: gasoil_premium_sub_10 | CG1: gasoil_premium_sub_11 | CH1: gasoil_premium_sub_12 | CI1: gasoil_regular_sub_1 | CJ1: gasoil_regular_sub_2 | CK1: gasoil_regular_sub_3 | CL1: gasoil_regular_sub_4 | CM1: gasoil_regular_sub_5 | CN1: gasoil_regular_sub_6 | CO1: gasoil_regular_sub_7 | CP1: gasoil_regular_sub_8 | CQ1: gasoil_regular_sub_9 | CR1: gasoil_regular_sub_10 | CS1: gasoil_regular_sub_11 | CT1: gasoil_regular_sub_12 | CU1: glp_sub_1 | CV1: glp_sub_2 | CW1: glp_sub_3 | CX1: glp_sub_4 | CY1: glp_sub_5 | CZ1: glp_sub_6 | DA1: glp_sub_7 | DB1: glp_sub_8 | DC1: glp_sub_9 | DD1: glp_sub_10 | DE1: glp_sub_11 | DF1: glp_sub_12 | DG1: gasolina_premium_sub_1 | DH1: gasolina_premium_sub_2 | DI1: gasolina_premium_sub_3 | DJ1: gasolina_premium_sub_4 | DK1: gasolina_premium_sub_5 | DL1: gasolina_premium_sub_6 | DM1: gasolina_premium_sub_7 | DN1: gasolina_premium_sub_8 | DO1: gasolina_premium_sub_9 | DP1: gasolina_premium_sub_10 | DQ1: gasolina_premium_sub_11 | DR1: gasolina_premium_sub_12 | DS1: gasolina_regular_sub_1 | DT1: gasolina_regular_sub_2 | DU1: gasolina_regular_sub_3 | DV1: gasolina_regular_sub_4 | DW1: gasolina_regular_sub_5 | DX1: gasolina_regular_sub_6 | DY1: gasolina_regular_sub_7 | DZ1: gasolina_regular_sub_8 | EA1: gasolina_regular_sub_9 | EB1: gasolina_regular_sub_10 | EC1: gasolina_regular_sub_11 | ED1: gasolina_regular_sub_12 | EE1: gasoil_1 | EF1: gasoil_2 | EG1: gasoil_3 | EH1: gasoil_4 | EI1: gasoil_5 | EJ1: gasoil_6 | EK1: gasoil_7 | EL1: gasoil_8 | EM1: gasoil_9 | EN1: gasoil_10 | EO1: gasoil_11 | EP1: gasoil_12 | EQ1: gasolina_premium_1 | ER1: gasolina_premium_2 | ES1: gasolina_premium_3 | ET1: gasolina_premium_4 | EU1: gasolina_premium_5 | EV1: gasolina_premium_6 | EW1: gasolina_premium_7 | EX1: gasolina_premium_8 | EY1: gasolina_premium_9 | EZ1: gasolina_premium_10 | FA1: gasolina_premium_11 | FB1: gasolina_premium_12 | FC1: gasolina_regular_1 | FD1: gasolina_regular_2 | FE1: gasolina_regular_3 | FF1: gasolina_regular_4 | FG1: gasolina_regular_5 | FH1: gasolina_regular_6 | FI1: gasolina_regular_7 | FJ1: gasolina_regular_8 | FK1: gasolina_regular_9 | FL1: gasolina_regular_10 | FM1: gasolina_regular_11 | FN1: gasolina_regular_12 | FO1: glp_1 | FP1: glp_2 | FQ1: glp_3 | FR1: glp_4 | FS1: glp_5 | FT1: glp_6 | FU1: glp_7 | FV1: glp_8 | FW1: glp_9 | FX1: glp_10 | FY1: glp_11 | FZ1: glp_12 | GA1: nom_sgas
A2: 0 | B2: 1 | C2: 0 | D2: 0 | E2: 0 | F2: 0 | G2: 0 | H2: 0 | I2: 0 | J2: 0 | K2: 0 | L2: 0 | M2: 0 | N2: 0 | O2: 242 | P2: 242 | Q2: 251 | R2: 264 | S2: 281 | T2: 292 | U2: 292 | V2: 292 | W2: 292 | X2: 292 | Y2: 292 | Z2: 292 | AA2: 242 | AB2: 242 | AC2: 251 | AD2: 264 | AE2: 281 | AF2: 292 | AG2: 292 | AH2: 292 | AI2: 292 | AJ2: 292 | AK2: 292 | AL2: 292 | AM2: 290 | AN2: 290 | AO2: 299 | AP2: 312 | AQ2: 329 | AR2: 340 | AS2: 340 | AT2: 340 | AU2: 340 | AV2: 340 | AW2: 340 | AX2: 340 | AY2: 272 | AZ2: 272 | BA2: 281 | BB2: 293 | BC2: 304 | BD2: 310 | BE2: 310 | BF2: 310 | BG2: 310 | BH2: 310 | BI2: 310 | BJ2: 310 | BK2: 272 | BL2: 272 | BM2: 281 | BN2: 293 | BO2: 304 | BP2: 310 | BQ2: 310 | BR2: 310 | BS2: 310 | BT2: 310 | BU2: 310 | BV2: 310 | BW2: 0 | BX2: 0 | BY2: 0 | BZ2: 0 | CA2: 0 | CB2: 0 | CC2: 0 | CD2: 0 | CE2: 0 | CF2: 0 | CG2: 0 | CH2: 0 | CI2: 0 | CJ2: 0 | CK2: 0 | CL2: 0 | CM2: 0 | CN2: 0 | CO2: 0 | CP2: 0 | CQ2: 0 | CR2: 0 | CS2: 0 | CT2: 0 | CU2: 0 | CV2: 0 | CW2: 0 | CX2: 0 | CY2: 0 | CZ2: 0 | DA2: 0 | DB2: 0 | DC2: 0 | DD2: 0 | DE2: 0 | DF2: 0 | DG2: 0 | DH2: 0 | DI2: 0 | DJ2: 0 | DK2: 0 | DL2: 0 | DM2: 0 | DN2: 0 | DO2: 0 | DP2: 0 | DQ2: 0 | DR2: 0 | DS2: 0 | DT2: 0 | DU2: 0 | DV2: 0 | DW2: 0 | DX2: 0 | DY2: 0 | DZ2: 0 | EA2: 0 | EB2: 0 | EC2: 0 | ED2: 0 | EE2: 0.073428055 | EF2: 0.077454216 | EG2: 0.085545593 | EH2: 0.073554749 | EI2: 0.086175065 | EJ2: 0.086373717 | EK2: 0.084908729 | EL2: 0.085906809 | EM2: 0.086656186 | EN2: 0.084422232 | EO2: 0.084252924 | EP2: 0.091321725 | EQ2: 0.079598218 | ER2: 0.076057135 | ES2: 0.08364665 | ET2: 0.07397495 | EU2: 0.08488576 | EV2: 0.083960953 | EW2: 0.081939694 | EX2: 0.086857108 | EY2: 0.085477769 | EZ2: 0.085777341 | FA2: 0.082567137 | FB2: 0.095257286 | FC2: 0.084361013 | FD2: 0.077783124 | FE2: 0.085567548 | FF2: 0.076073102 | FG2: 0.085309071 | FH2: 0.084870666 | FI2: 0.083751784 | FJ2: 0.088617202 | FK2: 0.084406801 | FL2: 0.080906747 | FM2: 0.078218999 | FN2: 0.090133944 | FO2: 0.082503397 | FP2: 0.080533724 | FQ2: 0.087406739 | FR2: 0.077561592 | FS2: 0.086125914 | FT2: 0.084101038 | FU2: 0.081359462 | FV2: 0.085530431 | FW2: 0.082438992 | FX2: 0.081477927 | FY2: 0.080596352 | FZ2: 0.090364432 | GA2: sin subsidio
A3: 1 | B3: 1 | C3: 0 | D3: 0 | E3: 0 | F3: 0 | G3: 1 | H3: 1 | I3: 1 | J3: 1 | K3: 1 | L3: 1 | M3: 1 | N3: 1 | O3: 242 | P3: 242 | Q3: 251 | R3: 264 | S3: 281 | T3: 292 | U3: 292 | V3: 292 | W3: 292 | X3: 292 | Y3: 292 | Z3: 292 | AA3: 242 | AB3: 242 | AC3: 251 | AD3: 264 | AE3: 281 | AF3: 292 | AG3: 292 | AH3: 292 | AI3: 292 | AJ3: 292 | AK3: 292 | AL3: 292 | AM3: 290 | AN3: 290 | AO3: 299 | AP3: 312 | AQ3: 329 | AR3: 340 | AS3: 340 | AT3: 340 | AU3: 340 | AV3: 340 | AW3: 340 | AX3: 340 | AY3: 272 | AZ3: 272 | BA3: 281 | BB3: 293 | BC3: 304 | BD3: 310 | BE3: 310 | BF3: 310 | BG3: 310 | BH3: 310 | BI3: 310 | BJ3: 310 | BK3: 272 | BL3: 272 | BM3: 281 | BN3: 293 | BO3: 304 | BP3: 310 | BQ3: 310 | BR3: 310 | BS3: 310 | BT3: 310 | BU3: 310 | BV3: 310 | BW3: 0 | BX3: 0 | BY3: 0 | BZ3: 0 | CA3: 53.3 | CB3: 53.3 | CC3: 53.3 | CD3: 53.3 | CE3: 53.3 | CF3: 53.3 | CG3: 53.3 | CH3: 53.3 | CI3: 0 | CJ3: 0 | CK3: 0 | CL3: 0 | CM3: 50.6 | CN3: 50.6 | CO3: 50.6 | CP3: 50.6 | CQ3: 50.6 | CR3: 50.6 | CS3: 50.6 | CT3: 50.6 | CU3: 0 | CV3: 0 | CW3: 0 | CX3: 0 | CY3: 50.6 | CZ3: 50.6 | DA3: 50.6 | DB3: 50.6 | DC3: 50.6 | DD3: 50.6 | DE3: 50.6 | DF3: 50.6 | DG3: 0 | DH3: 0 | DI3: 0 | DJ3: 0 | DK3: 23.1 | DL3: 23.1 | DM3: 23.1 | DN3: 23.1 | DO3: 23.1 | DP3: 23.1 | DQ3: 23.1 | DR3: 23.1 | DS3: 0 | DT3: 0 | DU3: 0 | DV3: 0 | DW3: 39.4 | DX3: 39.4 | DY3: 39.4 | DZ3: 39.4 | EA3: 39.4 | EB3: 39.4 | EC3: 39.4 | ED3: 39.4 | GA3: subsidio combustibles
O18: gasoil_precio_1 | Q18: gasoil_precio_1 | R18: gasoil_precio_2 | S18: gasoil_precio_3 | T18: gasoil_precio_4 | U18: gasoil_precio_5 | V18: gasoil_precio_6 | W18: gasoil_precio_7 | X18: gasoil_precio_8 | Y18: gasoil_precio_9 | Z18: gasoil_precio_10 | AA18: gasoil_precio_11 | AB18: gasoil_precio_12 | AC18: gasolina_premium_precio_1 | AD18: gasolina_premium_precio_2 | AE18: gasolina_premium_precio_3 | AF18: gasolina_premium_precio_4 | AG18: gasolina_premium_precio_5 | AH18: gasolina_premium_precio_6 | AI18: gasolina_premium_precio_7 | AJ18: gasolina_premium_precio_8 | AK18: gasolina_premium_precio_9 | AL18: gasolina_premium_precio_10 | AM18: gasolina_premium_precio_11 | AN18: gasolina_premium_precio_12 | AO18: gasolina_regular_precio_1 | AP18: gasolina_regular_precio_2 | AQ18: gasolina_regular_precio_3 | AR18: gasolina_regular_precio_4 | AS18: gasolina_regular_precio_5 | AT18: gasolina_regular_precio_6 | AU18: gasolina_regular_precio_7 | AV18: gasolina_regular_precio_8 | AW18: gasolina_regular_precio_9 | AX18: gasolina_regular_precio_10 | AY18: gasolina_regular_precio_11 | AZ18: gasolina_regular_precio_12 | BA18: gasoil_sub_1 | BB18: gasoil_sub_2 | BC18: gasoil_sub_3 | BD18: gasoil_sub_4 | BE18: gasoil_sub_5 | BF18: gasoil_sub_6 | BG18: gasoil_sub_7 | BH18: gasoil_sub_8 | BI18: gasoil_sub_9 | BJ18: gasoil_sub_10 | BK18: gasoil_sub_11 | BL18: gasoil_sub_12 | BM18: gasolina_premium_sub_1 | BN18: gasolina_premium_sub_2 | BO18: gasolina_premium_sub_3 | BP18: gasolina_premium_sub_4 | BQ18: gasolina_premium_sub_5 | BR18: gasolina_premium_sub_6 | BS18: gasolina_premium_sub_7 | BT18: gasolina_premium_sub_8 | BU18: gasolina_premium_sub_9 | BV18: gasolina_premium_sub_10 | BW18: gasolina_premium_sub_11 | BX18: gasolina_premium_sub_12 | BY18: gasolina_regular_sub_1 | BZ18: gasolina_regular_sub_2 | CA18: gasolina_regular_sub_3 | CB18: gasolina_regular_sub_4 | CC18: gasolina_regular_sub_5 | CD18: gasolina_regular_sub_6 | CE18: gasolina_regular_sub_7 | CF18: gasolina_regular_sub_8 | CG18: gasolina_regular_sub_9 | CH18: gasolina_regular_sub_10
O19: gasoil_precio_2
O20: gasoil_precio_3
O21: gasoil_precio_4
O22: gasoil_precio_5
O23: gasoil_precio_6
O24: gasoil_precio_7
O25: gasoil_precio_8
O26: gasoil_precio_9
O27: gasoil_precio_10
O28: gasoil_precio_11
O29: gasoil_precio_12
O30: gasolina_premium_precio_1
... O89: gasolina_regular_sub_12

Sheet sim_comp
A1: sim_comp | B1: activo | C1: grupo_com | D1: metodo_com | E1: valor_com | F1: decil_com | G1: icv_com | H1: decil_est
A2: 0 | B2: 1 | C2: 2 | D2: 2 | E2: 0 | H2: 4
A3: 1 | B3: 1 | C3: 2 | D3: 2 | E3: 500 | F3: 2 | G3: 2 | H3: 4
A4: 2 | B4: 0 | D4: 2 | E4: 500 | F4: 4
A5: 3 | B5: 0
A6: 4 | B6: 0

Sheet sensibilidad
A1: esc_sens | B1: activo | C1: comp_size1 | D1: comp_size2 | E1: comp_size3 | F1: comp_size4 | G1: comp_size5 | H1: comp_share1 | I1: comp_share2 | J1: comp_share3 | K1: comp_share4 | L1: comp_share5 | M1: sen_sim1 | N1: sen_sim2 | O1: sen_sim3 | P1: sen_sim4 | Q1: sen_sim5
A2: 1 | B2: 1 | C2: 1 | D2: 1.25 | E2: 1.5 | F2: 2 | G2: 3 | H2: 0.87 | I2: =H2 -> 0.87 | J2: =I2 -> 0.87 | K2: =J2 -> 0.87 | L2: =K2 -> 0.87 | M2: 3 | N2: 4 | O2: 9 | P2: 10
A3: 2 | B3: 1 | C3: 1 | D3: 1 | E3: 1 | F3: 1 | G3: 1 | H3: 0.87 | I3: 0.905 | J3: 0.93 | K3: 0.95 | L3: 0.97 | M3: 3 | N3: 4 | O3: 9 | P3: 10

Sheet tipo_establecimiento
A1: id_tipo_establecimiento | B1: des_tipo_establecimiento | C1: pag1_u | D1: pag1_r | E1: pag2_u | F1: pag2_r | G1: pag3_u | H1: pag3_r | I1: pag4_u | J1: pag4_r
A2: 1 | B2: Acueductos | C2: 0 | D2: 0 | E2: 0 | F2: 0 | G2: 1 | H2: 1 | I2: 0 | J2: 0
A3: 2 | B3: Agencia online de turismo | C3: 1 | D3: 1 | E3: 1 | F3: 1 | G3: 1 | H3: 1 | I3: 1 | J3: 1
A4: 3 | B4: Agencias de viaje internacionales | C4: 1 | D4: 1 | E4: 1 | F4: 1 | G4: 1 | H4: 1 | I4: 1 | J4: 1
A5: 4 | B5: Agencias de viaje nacionales | C5: 1 | D5: 1 | E5: 1 | F5: 1 | G5: 1 | H5: 1 | I5: 1 | J5: 1
A6: 5 | B6: Almacenes de provisiones | C6: 1 | D6: 1 | E6: 1 | F6: 1 | G6: 1 | H6: 1 | I6: 1 | J6: 1
A7: 6 | B7: Armería | C7: 1 | D7: 1 | E7: 1 | F7: 1 | G7: 1 | H7: 1 | I7: 1 | J7: 1
A8: 7 | B8: Aseguradoras | C8: 1 | D8: 1 | E8: 1 | F8: 1 | G8: 1 | H8: 1 | I8: 1 | J8: 1
A9: 8 | B9: Asociación de ahorros y prestamos | C9: 1 | D9: 1 | E9: 1 | F9: 1 | G9: 1 | H9: 1 | I9: 1 | J9: 1
A10: 9 | B10: Asociaciones de choferes /prestadores independientes | C10: 0 | D10: 0 | E10: 0 | F10: 0 | G10: 1 | H10: 1 | I10: 1 | J10: 1
A11: 10 | B11: Ayuntamiento, recolectora de basura | C11: 0 | D11: 0 | E11: 0 | F11: 0 | G11: 1 | H11: 1 | I11: 0 | J11: 0
A12: 11 | B12: Banca comercial | C12: 1 | D12: 1 | E12: 1 | F12: 1 | G12: 1 | H12: 1 | I12: 1 | J12: 1
A13: 12 | B13: Banca de apuestas deportivas | C13: 1 | D13: 1 | E13: 1 | F13: 1 | G13: 1 | H13: 1 | I13: 1 | J13: 1
... A203: 205 | B203: Empresas de zonas francas | C203: 0 | D203: 0 | E203: 0 | F203: 0 | G203: 1 | H203: 1 | I203: 0 | J203: 0

Sheet resumen
A1: esc_resumen | B1: activo | C1: d_itbis | D1: d_isr | E1: d_subsidio | F1: d_descripcion
A2: 1 | B2: 1 | C2: 1 | D2: 1 | E2: 1 | F2: Comparación ITBIS
A3: 2 | B3: 1 | C3: 1 | D3: 1 | E3: 1 | F3: Comparación ITBIS
A4: 11 | B4: 1 | D4: 1 | F4: Comparación renta
